[2022-09-12 00:37:09,528] {taskinstance.py:876} INFO - Dependencies all met for <TaskInstance: parallel_dag.processing_tasks 2022-09-11T00:00:00+00:00 [queued]>
[2022-09-12 00:37:09,716] {taskinstance.py:876} INFO - Dependencies all met for <TaskInstance: parallel_dag.processing_tasks 2022-09-11T00:00:00+00:00 [queued]>
[2022-09-12 00:37:09,749] {taskinstance.py:1067} INFO - 
--------------------------------------------------------------------------------
[2022-09-12 00:37:09,749] {taskinstance.py:1068} INFO - Starting attempt 1 of 1
[2022-09-12 00:37:09,749] {taskinstance.py:1069} INFO - 
--------------------------------------------------------------------------------
[2022-09-12 00:37:10,045] {taskinstance.py:1087} INFO - Executing <Task(SubDagOperator): processing_tasks> on 2022-09-11T00:00:00+00:00
[2022-09-12 00:37:10,174] {standard_task_runner.py:52} INFO - Started process 240450 to run task
[2022-09-12 00:37:10,419] {standard_task_runner.py:76} INFO - Running: ['airflow', 'tasks', 'run', 'parallel_dag', 'processing_tasks', '2022-09-11T00:00:00+00:00', '--job-id', '10', '--pool', 'default_pool', '--raw', '--subdir', 'DAGS_FOLDER/parallel_dag.py', '--cfg-path', '/tmp/tmparb6_k3x', '--error-file', '/tmp/tmpegmt34ms']
[2022-09-12 00:37:10,472] {standard_task_runner.py:77} INFO - Job 10: Subtask processing_tasks
[2022-09-12 00:37:13,301] {logging_mixin.py:104} INFO - Running <TaskInstance: parallel_dag.processing_tasks 2022-09-11T00:00:00+00:00 [running]> on host airflowvm
[2022-09-12 00:37:14,200] {taskinstance.py:1280} INFO - Exporting the following env vars:
AIRFLOW_CTX_DAG_OWNER=airflow
AIRFLOW_CTX_DAG_ID=parallel_dag
AIRFLOW_CTX_TASK_ID=processing_tasks
AIRFLOW_CTX_EXECUTION_DATE=2022-09-11T00:00:00+00:00
AIRFLOW_CTX_DAG_RUN_ID=scheduled__2022-09-11T00:00:00+00:00
[2022-09-12 00:37:14,517] {subdag.py:155} INFO - Created DagRun: scheduled__2022-09-11T00:00:00+00:00
[2022-09-12 00:42:15,073] {taskinstance.py:1481} ERROR - Task failed with exception
Traceback (most recent call last):
  File "/home/airflow/sandbox/lib/python3.8/site-packages/airflow/models/taskinstance.py", line 1137, in _run_raw_task
    self._prepare_and_execute_task_with_callbacks(context, task)
  File "/home/airflow/sandbox/lib/python3.8/site-packages/airflow/models/taskinstance.py", line 1311, in _prepare_and_execute_task_with_callbacks
    result = self._execute_task(context, task_copy)
  File "/home/airflow/sandbox/lib/python3.8/site-packages/airflow/models/taskinstance.py", line 1341, in _execute_task
    result = task_copy.execute(context=context)
  File "/home/airflow/sandbox/lib/python3.8/site-packages/airflow/sensors/base.py", line 226, in execute
    while not self.poke(context):
  File "/home/airflow/sandbox/lib/python3.8/site-packages/airflow/operators/subdag.py", line 164, in poke
    return dag_run.state != State.RUNNING
AttributeError: 'NoneType' object has no attribute 'state'
[2022-09-12 00:42:15,093] {taskinstance.py:1524} INFO - Marking task as FAILED. dag_id=parallel_dag, task_id=processing_tasks, execution_date=20220911T000000, start_date=20220912T003709, end_date=20220912T004215
[2022-09-12 00:42:15,186] {local_task_job.py:151} INFO - Task exited with return code 1
