[2022-09-13 02:34:02,419] {taskinstance.py:876} INFO - Dependencies all met for <TaskInstance: xcom_dag.choose_model 2022-09-13T02:33:53.660173+00:00 [queued]>
[2022-09-13 02:34:02,471] {taskinstance.py:876} INFO - Dependencies all met for <TaskInstance: xcom_dag.choose_model 2022-09-13T02:33:53.660173+00:00 [queued]>
[2022-09-13 02:34:02,472] {taskinstance.py:1067} INFO - 
--------------------------------------------------------------------------------
[2022-09-13 02:34:02,472] {taskinstance.py:1068} INFO - Starting attempt 1 of 1
[2022-09-13 02:34:02,472] {taskinstance.py:1069} INFO - 
--------------------------------------------------------------------------------
[2022-09-13 02:34:02,493] {taskinstance.py:1087} INFO - Executing <Task(BranchPythonOperator): choose_model> on 2022-09-13T02:33:53.660173+00:00
[2022-09-13 02:34:02,496] {standard_task_runner.py:52} INFO - Started process 41259 to run task
[2022-09-13 02:34:02,525] {standard_task_runner.py:76} INFO - Running: ['airflow', 'tasks', 'run', 'xcom_dag', 'choose_model', '2022-09-13T02:33:53.660173+00:00', '--job-id', '46', '--pool', 'default_pool', '--raw', '--subdir', 'DAGS_FOLDER/xcom_dag.py', '--cfg-path', '/tmp/tmp1uim5g09', '--error-file', '/tmp/tmpdyj9q0vd']
[2022-09-13 02:34:02,528] {standard_task_runner.py:77} INFO - Job 46: Subtask choose_model
[2022-09-13 02:34:02,708] {logging_mixin.py:104} INFO - Running <TaskInstance: xcom_dag.choose_model 2022-09-13T02:33:53.660173+00:00 [running]> on host airflowvm
[2022-09-13 02:34:02,955] {taskinstance.py:1280} INFO - Exporting the following env vars:
AIRFLOW_CTX_DAG_OWNER=airflow
AIRFLOW_CTX_DAG_ID=xcom_dag
AIRFLOW_CTX_TASK_ID=choose_model
AIRFLOW_CTX_EXECUTION_DATE=2022-09-13T02:33:53.660173+00:00
AIRFLOW_CTX_DAG_RUN_ID=manual__2022-09-13T02:33:53.660173+00:00
[2022-09-13 02:34:02,977] {logging_mixin.py:104} INFO - these are your accuracies [None, None, None]
[2022-09-13 02:34:02,977] {taskinstance.py:1481} ERROR - Task failed with exception
Traceback (most recent call last):
  File "/home/airflow/sandbox/lib/python3.8/site-packages/airflow/models/taskinstance.py", line 1137, in _run_raw_task
    self._prepare_and_execute_task_with_callbacks(context, task)
  File "/home/airflow/sandbox/lib/python3.8/site-packages/airflow/models/taskinstance.py", line 1311, in _prepare_and_execute_task_with_callbacks
    result = self._execute_task(context, task_copy)
  File "/home/airflow/sandbox/lib/python3.8/site-packages/airflow/models/taskinstance.py", line 1341, in _execute_task
    result = task_copy.execute(context=context)
  File "/home/airflow/sandbox/lib/python3.8/site-packages/airflow/operators/python.py", line 179, in execute
    branch = super().execute(context)
  File "/home/airflow/sandbox/lib/python3.8/site-packages/airflow/operators/python.py", line 150, in execute
    return_value = self.execute_callable()
  File "/home/airflow/sandbox/lib/python3.8/site-packages/airflow/operators/python.py", line 161, in execute_callable
    return self.python_callable(*self.op_args, **self.op_kwargs)
  File "/home/airflow/airflow/dags/xcom_dag.py", line 27, in _choose_best_model
    if accuracy > 5:
TypeError: '>' not supported between instances of 'NoneType' and 'int'
[2022-09-13 02:34:02,980] {taskinstance.py:1524} INFO - Marking task as FAILED. dag_id=xcom_dag, task_id=choose_model, execution_date=20220913T023353, start_date=20220913T023402, end_date=20220913T023402
[2022-09-13 02:34:03,090] {local_task_job.py:151} INFO - Task exited with return code 1
